Traceback (most recent call last):
  File "/Users/gcohen/opt/anaconda3/lib/python3.7/site-packages/jupyter_cache/executors/utils.py", line 56, in single_nb_execution
    record_timing=False,
  File "/Users/gcohen/opt/anaconda3/lib/python3.7/site-packages/nbclient/client.py", line 1087, in execute
    return NotebookClient(nb=nb, resources=resources, km=km, **kwargs).execute()
  File "/Users/gcohen/opt/anaconda3/lib/python3.7/site-packages/nbclient/util.py", line 74, in wrapped
    return just_run(coro(*args, **kwargs))
  File "/Users/gcohen/opt/anaconda3/lib/python3.7/site-packages/nbclient/util.py", line 53, in just_run
    return loop.run_until_complete(coro)
  File "/Users/gcohen/opt/anaconda3/lib/python3.7/asyncio/base_events.py", line 587, in run_until_complete
    return future.result()
  File "/Users/gcohen/opt/anaconda3/lib/python3.7/site-packages/nbclient/client.py", line 541, in async_execute
    cell, index, execution_count=self.code_cells_executed + 1
  File "/Users/gcohen/opt/anaconda3/lib/python3.7/site-packages/nbclient/client.py", line 832, in async_execute_cell
    self._check_raise_for_error(cell, exec_reply)
  File "/Users/gcohen/opt/anaconda3/lib/python3.7/site-packages/nbclient/client.py", line 740, in _check_raise_for_error
    raise CellExecutionError.from_cell_and_msg(cell, exec_reply['content'])
nbclient.exceptions.CellExecutionError: An error occurred while executing the following cell:
------------------
# packages
library(tidyverse)
library(repr)
library(infer)
library(cowplot)
library(broom)

#data
dat <- read.csv("data/Assessment_2015.csv")
dat <- dat %>% filter(ASSESSCLAS=="Residential")  %>% 
        mutate(assess_val = ASSESSMENT / 1000)

set.seed(561)

dat_s <- sample_n(dat, 1000, replace = FALSE)

------------------

Error in library(infer): there is no package called ‘infer’
Traceback:

1. library(infer)
ERROR: Error in library(infer): there is no package called ‘infer’


